"use client"

import React, { Component, ErrorInfo, ReactNode } from "react"
import { Card, CardContent, CardHeader, CardTitle } from "@/components/ui/card"
import { Button } from "@/components/ui/button"
import { AlertTriangle, RefreshCw } from "lucide-react"

interface Props {
  children: ReactNode
  fallback?: ReactNode
}

interface State {
  hasError: boolean
  error?: Error
  errorInfo?: ErrorInfo
}

export class ErrorBoundary extends Component<Props, State> {
  constructor(props: Props) {
    super(props)
    this.state = { hasError: false }
  }

  static getDerivedStateFromError(error: Error): State {
    return { hasError: true, error }
  }

  componentDidCatch(error: Error, errorInfo: ErrorInfo) {
    console.error("Error caught by boundary:", error, errorInfo)
    this.setState({ error, errorInfo })
  }

  handleRetry = () => {
    this.setState({ hasError: false, error: undefined, errorInfo: undefined })
  }

  render() {
    if (this.state.hasError) {
      if (this.props.fallback) {
        return this.props.fallback
      }

      return (
        <div className="min-h-screen flex items-center justify-center bg-background p-4">
          <Card className="w-full max-w-md">
            <CardHeader className="text-center">
              <div className="mx-auto w-16 h-16 bg-red-100 rounded-full flex items-center justify-center mb-4">
                <AlertTriangle className="w-8 h-8 text-red-600" />
              </div>
              <CardTitle className="text-xl font-bold text-red-600">
                حدث خطأ غير متوقع
              </CardTitle>
            </CardHeader>
            <CardContent className="text-center space-y-4">
              <p className="text-muted-foreground">
                عذراً، حدث خطأ أثناء تحميل هذه الصفحة. يرجى المحاولة مرة أخرى.
              </p>
              
              {process.env.NODE_ENV === 'development' && this.state.error && (
                <details className="text-left">
                  <summary className="cursor-pointer text-sm font-medium mb-2">
                    تفاصيل الخطأ (للطور)
                  </summary>
                  <div className="bg-muted p-3 rounded text-xs font-mono overflow-auto">
                    <div className="mb-2">
                      <strong>الخطأ:</strong> {this.state.error.message}
                    </div>
                    {this.state.errorInfo && (
                      <div>
                        <strong>Stack:</strong>
                        <pre className="whitespace-pre-wrap mt-1">
                          {this.state.errorInfo.componentStack}
                        </pre>
                      </div>
                    )}
                  </div>
                </details>
              )}
              
              <div className="flex gap-2 justify-center">
                <Button onClick={this.handleRetry} className="flex items-center gap-2">
                  <RefreshCw className="w-4 h-4" />
                  إعادة المحاولة
                </Button>
                <Button 
                  variant="outline" 
                  onClick={() => window.location.href = '/'}
                >
                  العودة للرئيسية
                </Button>
              </div>
            </CardContent>
          </Card>
        </div>
      )
    }

    return this.props.children
  }
}

// Hook for functional components
export function useErrorHandler() {
  const [error, setError] = React.useState<Error | null>(null)

  const handleError = React.useCallback((error: Error) => {
    console.error("Error caught by hook:", error)
    setError(error)
  }, [])

  const clearError = React.useCallback(() => {
    setError(null)
  }, [])

  return { error, handleError, clearError }
} 